# 220503TIL_Java내용정리 :memo:
## Exception (예외 처리)  :x:
**예외 처리가 왜 필요한가?**
- 실제 서비스를 제공하는 프로그램에서 오류가 생기면 서비스가 중지되므로 문제가 심각해짐
- 이러한 비정상적인 종료를 줄이고, 사전에 발생할 오류에 대해 방지하기 위해 예외처리를 진행한다.

###  Error & Exception  :interrobang:
실행오류(runtime error)는 크게 두가지로 나뉜다.
1. JVM에서 발생하는 시스템 오류(error)
	- 사용 가능한 동적 메모리가 없는 경우, 스택메모리의 오버플로가 발생한 경우
	- 이러한 시스템 오류는 프로그램에서 제어할 수 없다.
2. 예외(exception)
	- 예외는 프로그램에서 제어가 가능하다. 
	- 프로그램에서 파일을 읽어 사용하려는데 파일이 없는 경우, 네트워크로 데이터를 전송하려는데 연경이 안 된 경우 등이 있다.

자바에서 제공하는 오류 클래스 와  예외 클래스는 **Throwable** 클래스에서 상속 받는다. 
#### Exception
- 프로그램에서 처리하는 예외 클래스의 최상위 클래스는 **Exception**클래스이다.
- 크게 사용 빈도가 높은 클래스는 입출력 예외 처리에 대한 클래스 **IOException** 과 실행 오류 예외 처리에 대한 클래스 **RuntimeException**이 있다. 

각각의 예외클래스의 세부 클래스는 코드를 통해 주석에 설명을 달아 놓겠다.
### try-catch-finally block  :recycle:
- 예외 상황이 발생 했을 때에 처리하는 방법 중 하나
1. try block : 예외가 발생할 가능성이 있는 코드를 작성
2. catch block: try block 에서 코드 실행 중에 예외가 발생하면 해당 블록에서 예외를 처리한다.
3. finally block: 일단 try block 에서 코드가 실행되면 어떤 경우에도 반드시 해당 블록은 실행된다.(try,catch문에서 "return"이 있더라고 수행됨.)
4.  try구문에서 강제적으로 예외 발생하는 키워드는 **throw** 이다. 예외를 넘기는 **throws** 예약어와 헷갈리면 안된다!

**코드내용**
> 내가 지정한 number 필드에 값을 지정하고 random한 값을 분모로 위치하여 내가 지정한 10번의 값을 출력하고 싶다.
> 하지만 random한 값이여서 분모에 **0**값도 들어갈 수 있다.
> 에러가 발생하면 프로그램이 중지되므로 try-catch 값으로 예외가 발생시 "분모에 0이 들어가면 안됩니다." 와 예외 텍스트를 보여주고 10번까지 반복을 진행한다.
```java
//Ex1.java
//초기의 예외처리를 못한 코드
public class Ex1 {
	public static void main(String[] args) {
		int number = 100;
		int result = 0;
		
		//number값을 랜덤값으로 나눈 결과 출력
		for(int i =0; i< 10; i++) {
			result = number / (int)(Math.random()*10);
			System.out.println(result);
		}
	}
}
```
출력값
>14
>50
>12
>11
>Exception in thread "main" java.lang.ArithmeticException: / by zero
>	at com.Ex1.main(Ex1.java:10) // 10번을 채 반복하지 못하고 종료
```java
public class Ex2 {
	public static void main(String[] args) {
		int number = 100;
		int result = 0;
		
		//number값을 랜덤값으로 나눈 결과 출력
		for(int i =0; i< 10; i++) {
			try { // 비정상적인 종료 (분모가 0이 들어가는 경우) 예외처리를 해보자 try
			result = number / (int)(Math.random()*10);
			System.out.println(result);
			} catch(ArithmeticException exception) { //exception이라는 인스턴스는 코드의 실행과정에서 0으로 나누는 예외가 발생하면 그때 
				//new ArithmeticException(); 인스턴스를 생성하고, exception 변수에 초기화.
				//exception = new new ArithmeticException(); 이루어짐.
				
				// 즉, 0으로 나누는 예외가 발생하기 전까지는 exception 변수는 선언만 되어있는 상태인데,
				//0으로 나누는 예외가 발생하면 그때 인스턴스가 생성되서 exception 변수가 초기화됨.
				System.out.println("분모에 0이 들어가면 안됩니다.");// 마치 if문처럼 에러가 발생하면 catch블록으로 이동
				System.out.println(exception); // toString()을 붙인것처럼 예외 텍스트 그대로 나온다.
			}//try-catch end
		}// for end
	}//main end
}
```
출력값
>12
>20
>20
>20
>14
>분모에 0이 들어가면 안됩니다.
>java.lang.ArithmeticException: / by zero 
>14
>25
>20
>11
>//예외가 발생하더라고 내가 원하는 프로그램 종료 없이 10번의 반복은 만족

### **try-catch-finally block 예시**
**코드내용**
> class 메서드와 멤버 메서드를 각각 만들고, 멤버 메서드인 method1에서 try-catch-finally 로 예외 발생시 catch블록에서 예외 발생 메세지를 출력한다.
> finally 블록에서는 예외처리 진행과 상관없이 진행되는 것을 try문에 return값을 넣어서 증명한다.
> 마지막으로 클래스 메서드에서 최종적으로 마무리 짓는 출력문을 찍어 낸다.

```java
public class Ex4 {
	
	//Ex4 class의 멤버 메서드 중에서 클래스 메서드 (static)
	public static void main(String[] args) {
		method1();
		System.out.println("method1()의 수행 종료. main() 복귀");
	}//main end
	
	//Ex4 class의 또다른 멤버 메서드
	public static void method1() {
		try {
			System.out.println("method1() 호출되었음.");
			System.out.println(3/0);
			return; //원래 return은 만나면 코드를 종료하지만 finally는 return이 있어도 실행이 된다.
		} catch (Exception e) {
			e.printStackTrace();
		} finally { // 예외처리 진행 여부에 상관없이 무조건 실행되는 부분
			System.out.println("method1() finally block이 실행 되었음.");
		} 
	}//method1 end
}//class end
```
출력값
>method1() 호출되었음.
>java.lang.ArithmeticException: / by zero
>	at com.Ex4.method1(Ex4.java:15)
>	at com.Ex4.main(Ex4.java:7)
>method1() finally block이 실행 되었음.
>method1()의 수행 종료. main() 복귀
>이처럼 예외가 발생하더라도 처리후 마지막까지 프로그램이 계속 수행되었음을 알 수 있다.

### throws :hourglass:
앞서 예외처리 방법 중 try-catch 구문으로 감싸서 예외를 처리하였다. 이제 다른 예외 처리 방법인 **throws**의 방법을 알아보자.
- 예외를 해당 메서드에서 처리하지 않고 미룬 후 메서드를 호출하여 사용하는 부분에서 예외를 처리하는 방법이다. 

throws는 코드 예시를 통해서 알아보자.

**코드내용**
> 멤버메서드 method2에서  발생한 예외를 method1 에서 예외처리의 책임을 떠맡는다.
> 만약에 method1에서도 **throws**를 하면 멤버 메서드 main에서 처리에 대한 책임을 맡게 된다.
```java
public class MethodEx1 {
	//MethodEx1의 멤버 메서드
	public static void main(String[] args) throws Exception { // main 메서드에 예외를 넘겨 받았다.
		method1();
	}
	// MethodEx1dml 멤버 메서드 2 
	static void method1() throws Exception { // 이렇게 계속 예외처리를 떠넘기면 문법적 예외는 없겠지만 지금 예외에대해 처리가 안됐다. 
		method2();
		System.out.println("method1() 호출");
	}
	
	// MethodEx1dml 멤버 메서드 3
	static void method2() throws Exception { // method2() 내부에서 예외가 발생하면,
		// 해당 예외에 대한 예외 처리를 method2를 호출한 호출부에서 처리하도록 책임을 떠넘김.
		System.out.println(3/0); // 예외 발생
	}
}
```
> 이처럼 어떤 메서드가 예외처리에 대해 떠맡게 되면 어디선가 처리가 되어야 한다. 
> 그러지 않는다면 오류를 발생하고 방치해놓는 것이다.
> 멤버 메서드 method1에서 예외처리를 하려면
>		try {
>			method2();			
>		} catch (Exception e) {
>			e.printStackTrace();
>		}
>이 코드로 수정하면 예외처리를 수행하는 것이다.

### Checked Exception & Unchecked (Runtime)Exception :milky_way:
* 이 두가지의 명확한 구분 기준은 예외처리를 필수성의 여부이다. 
* Checked Exception 는 컴파일 단계에서 예외가 발생하므로 명시적으로 예외처리를 해야한다.
* Unchecked (Runtime)Exception 는 명시적으로 예외처리를 하지 않아도 된다. 대부분이 개발자의 부주의로 인한 발생이 대부분이, 예측하지 못했던 상황이 아님. (실행 과정 중에서 발견됨.)

| | Plugin | README |
|------ | ------ | ------ |
|처리여부 | 반드시 예외를 처리 | 명시적인 처리를 강제 받지 않음|
|확인시점 | 컴파일 단계 | 실행단계 |
|대표적인 Exception | IOException(입출력관련) | RuntimeException,NullPointerException |


